<?xml version="1.0" ?>
<!-- =================================================================================== -->
<!-- |    This document was autogenerated by xacro from /home/rosjg/project_ws/src/motoman_gp4/gp4_gazebo/urdf/gp4_main.xacro | -->
<!-- |    EDITING THIS FILE BY HAND IS NOT RECOMMENDED                                 | -->
<!-- =================================================================================== -->
<robot name="gp4_main">
    <!-- link list -->
    <link name="base_link">
        <visual>
            <geometry>
                <mesh filename="package://gp4_description/meshes/gp4/visual/base_link.dae" />
            </geometry>
            <material name="">
                <color rgba="0.12941176470588237 0.14901960784313725 0.7490196078431373 1.0" />
            </material>
        </visual>
        <collision>
            <geometry>
                <mesh filename="package://gp4_description/meshes/gp4/collision/base_link.stl" />
            </geometry>
        </collision>
        <inertial>
            <mass value="23.085357" />
            <origin rpy="0.0 0.0 0.0" xyz="0.007579 0.000017 0.180670" />
            <inertia ixx="0.343576" ixy="-0.000062" ixz="-0.002079" iyy="0.336217" iyz="-0.000014" izz="0.334050" />
        </inertial>
    </link>
    <link name="link_1_s">
        <visual>
            <geometry>
                <mesh filename="package://gp4_description/meshes/gp4/visual/link_1_s.dae" />
            </geometry>
            <material name="">
                <color rgba="0.12941176470588237 0.14901960784313725 0.7490196078431373 1.0" />
            </material>
        </visual>
        <collision>
            <geometry>
                <mesh filename="package://gp4_description/meshes/gp4/collision/link_1_s.stl" />
            </geometry>
        </collision>
        <inertial>
            <mass value="45.357763" />
            <origin rpy="0.0 0.0 0.0" xyz="0.085479 -0.002547 -0.040488" />
            <inertia ixx="0.839141" ixy="0.022637" ixz="0.162457" iyy="1.030146" iyz="0.027416" izz="1.064698" />
        </inertial>
    </link>
    <link name="link_2_l">
        <visual>
            <geometry>
                <mesh filename="package://gp4_description/meshes/gp4/visual/link_2_l.dae" />
            </geometry>
            <material name="">
                <color rgba="0.12941176470588237 0.14901960784313725 0.7490196078431373 1.0" />
            </material>
        </visual>
        <collision>
            <geometry>
                <mesh filename="package://gp4_description/meshes/gp4/collision/link_2_l.stl" />
            </geometry>
        </collision>
        <inertial>
            <mass value="51.266495" />
            <origin rpy="0.0 0.0 0.0" xyz="-0.000002 0.264164 0.347704" />
            <inertia ixx="5.272800" ixy="0.000010" ixz="0.000017" iyy="5.536809" iyz="-0.008261" izz="0.486191" />
        </inertial>
    </link>
    <link name="link_3_u">
        <visual>
            <geometry>
                <mesh filename="package://gp4_description/meshes/gp4/visual/link_3_u.dae" />
            </geometry>
            <material name="">
                <color rgba="0.12941176470588237 0.14901960784313725 0.7490196078431373 1.0" />
            </material>
        </visual>
        <collision>
            <geometry>
                <mesh filename="package://gp4_description/meshes/gp4/collision/link_3_u.stl" />
            </geometry>
        </collision>
        <inertial>
            <mass value="19.754401" />
            <origin rpy="0.0 0.0 0.0" xyz="-0.000255 0.016478 -0.003819" />
            <inertia ixx="0.249388" ixy="-0.004901" ixz="0.004825" iyy="0.211780" iyz="0.000574" izz="0.238488" />
        </inertial>
    </link>
    <link name="link_4_r">
        <visual>
            <geometry>
                <mesh filename="package://gp4_description/meshes/gp4/visual/link_4_r.dae" />
            </geometry>
            <material name="">
                <color rgba="0.12941176470588237 0.14901960784313725 0.7490196078431373 1.0" />
            </material>
        </visual>
        <collision>
            <geometry>
                <mesh filename="package://gp4_description/meshes/gp4/collision/link_4_r.stl" />
            </geometry>
        </collision>
        <inertial>
            <mass value="15.287896" />
            <origin rpy="0.0 0.0 0.0" xyz="-0.015515 0.000164 0.340348" />
            <inertia ixx="0.331593" ixy="0.000055" ixz="-0.010688" iyy="0.320895" iyz="0.000058" izz="0.086557" />
        </inertial>
    </link>
    <link name="link_5_b">
        <visual>
            <geometry>
                <mesh filename="package://gp4_description/meshes/gp4/visual/link_5_b.dae" />
            </geometry>
            <material name="">
                <color rgba="0.12941176470588237 0.14901960784313725 0.7490196078431373 1.0" />
            </material>
        </visual>
        <collision>
            <geometry>
                <mesh filename="package://gp4_description/meshes/gp4/collision/link_5_b.stl" />
            </geometry>
        </collision>
        <inertial>
            <mass value="0.548088" />
            <origin rpy="0.0 0.0 0.0" xyz="0.000000 -0.000347 0.023671" />
            <inertia ixx="0.000876" ixy="0.000000" ixz="0.000000" iyy="0.000889" iyz="0.000005" izz="0.000412" />
        </inertial>
    </link>
    <link name="link_6_t">
        <visual>
            <geometry>
                <mesh filename="package://gp4_description/meshes/gp4/visual/link_6_t.dae" />
            </geometry>
            <material name="">
                <color rgba="0.8 0.8 0.8 1" />
            </material>
        </visual>
        <collision>
            <geometry>
                <mesh filename="package://gp4_description/meshes/gp4/collision/link_6_t.stl" />
            </geometry>
        </collision>
        <inertial>
            <mass value="0.038484" />
            <origin rpy="0.0 0.0 0.0" xyz="-0.000245 0.000000 -0.007626" />
            <inertia ixx="0.000011" ixy="0.000000" ixz="0.000000" iyy="0.000011" iyz="0.000000" izz="0.000021" />
        </inertial>
    </link>
    <!-- end of link list -->
    <!-- joint list -->
    <joint name="joint_1_s" type="revolute">
        <parent link="base_link" />
        <child link="link_1_s" />
        <origin rpy="0 0 0" xyz="0 0 0.330" />
        <axis xyz="0 0 1" />
        <limit effort="220.5" lower="-2.9670597283903604" upper="2.9670597283903604" velocity="8.115781021773632" />
    </joint>
    <joint name="joint_2_l" type="revolute">
        <parent link="link_1_s" />
        <child link="link_2_l" />
        <origin rpy="0 0 0" xyz="0 0 0" />
        <axis xyz="0 1 0" />
        <limit effort="305.76" lower="-1.9198621771937625" upper="2.2689280275926285" velocity="8.115781021773632" />
    </joint>
    <joint name="joint_3_u" type="revolute">
        <parent link="link_2_l" />
        <child link="link_3_u" />
        <origin rpy="0 0 0" xyz="0 0 0.260" />
        <axis xyz="0 -1 0" />
        <limit effort="95.55" lower="-1.1344640137963142" upper="3.490658503988659" velocity="9.16297857297023" />
    </joint>
    <joint name="joint_4_r" type="revolute">
        <parent link="link_3_u" />
        <child link="link_4_r" />
        <origin rpy="0 0 0" xyz="0.290 0 0.015" />
        <axis xyz="-1 0 0" />
        <limit effort="48.02" lower="-3.490658503988659" upper="3.490658503988659" velocity="9.861110273767961" />
    </joint>
    <joint name="joint_5_b" type="revolute">
        <parent link="link_4_r" />
        <child link="link_5_b" />
        <origin rpy="0 0 0" xyz="0 0 0" />
        <axis xyz="0 -1 0" />
        <limit effort="38.42" lower="-2.1467549799530254" upper="2.1467549799530254" velocity="9.861110273767961" />
    </joint>
    <joint name="joint_6_t" type="revolute">
        <parent link="link_5_b" />
        <child link="link_6_t" />
        <origin rpy="0 0 0" xyz="0 0 0" />
        <axis xyz="-1 0 0" />
        <limit effort="16.46" lower="-7.941248096574199" upper="7.941248096574199" velocity="17.453292519943297" />
    </joint>
    <!-- end of joint list -->
    <!-- ROS-Industrial 'flange' frame: attachment point for EEF models -->
    <link name="flange" />
    <joint name="joint_6_t-flange" type="fixed">
        <origin rpy="0 0 0" xyz="0.072 0 0" />
        <parent link="link_6_t" />
        <child link="flange" />
    </joint>
    <!-- ROS-Industrial 'tool0' frame: all-zeros tool frame -->
    <link name="tool0" />
    <joint name="flange-tool0" type="fixed">
        <origin rpy="3.141592653589793 -1.5707963267948966 0" xyz="0 0 0" />
        <parent link="flange" />
        <child link="tool0" />
    </joint>
    <!-- ROS base_link to Robot Manufacturer World Coordinates transform -->
    <link name="base" />
    <joint name="base_link-base" type="fixed">
        <origin rpy="0 0 0" xyz="0 0 0.330" />
        <parent link="base_link" />
        <child link="base" />
    </joint>
    <!-- transmission list -->
    <transmission name="tran1">
        <robotNamespace>/</robotNamespace>
        <type>transmission_interface/SimpleTransmission</type>
        <joint name="joint_1_s">
            <hardwareInterface>hardware_interface/PositionJointInterface</hardwareInterface>
        </joint>
        <actuator name="motor1">
            <mechanicalReduction>1</mechanicalReduction>
            <hardwareInterface>hardware_interface/PositionJointInterface</hardwareInterface>
        </actuator>
    </transmission>
    <transmission name="tran2">
        <robotNamespace>/</robotNamespace>
        <type>transmission_interface/SimpleTransmission</type>
        <joint name="joint_2_l">
            <hardwareInterface>hardware_interface/PositionJointInterface</hardwareInterface>
        </joint>
        <actuator name="motor2">
            <mechanicalReduction>1</mechanicalReduction>
            <hardwareInterface>hardware_interface/PositionJointInterface</hardwareInterface>
        </actuator>
    </transmission>
    <transmission name="tran3">
        <robotNamespace>/</robotNamespace>
        <type>transmission_interface/SimpleTransmission</type>
        <joint name="joint_3_u">
            <hardwareInterface>hardware_interface/PositionJointInterface</hardwareInterface>
        </joint>
        <actuator name="motor3">
            <mechanicalReduction>1</mechanicalReduction>
            <hardwareInterface>hardware_interface/PositionJointInterface</hardwareInterface>
        </actuator>
    </transmission>
    <transmission name="tran4">
        <robotNamespace>/</robotNamespace>
        <type>transmission_interface/SimpleTransmission</type>
        <joint name="joint_4_r">
            <hardwareInterface>hardware_interface/PositionJointInterface</hardwareInterface>
        </joint>
        <actuator name="motor4">
            <mechanicalReduction>1</mechanicalReduction>
            <hardwareInterface>hardware_interface/PositionJointInterface</hardwareInterface>
        </actuator>
    </transmission>
    <transmission name="tran5">
        <robotNamespace>/</robotNamespace>
        <type>transmission_interface/SimpleTransmission</type>
        <joint name="joint_5_b">
            <hardwareInterface>hardware_interface/PositionJointInterface</hardwareInterface>
        </joint>
        <actuator name="motor5">
            <mechanicalReduction>1</mechanicalReduction>
            <hardwareInterface>hardware_interface/PositionJointInterface</hardwareInterface>
        </actuator>
    </transmission>
    <transmission name="tran6">
        <robotNamespace>/</robotNamespace>
        <type>transmission_interface/SimpleTransmission</type>
        <joint name="joint_6_t">
            <hardwareInterface>hardware_interface/PositionJointInterface</hardwareInterface>
        </joint>
        <actuator name="motor6">
            <mechanicalReduction>1</mechanicalReduction>
            <hardwareInterface>hardware_interface/PositionJointInterface</hardwareInterface>
        </actuator>
    </transmission>
    <!-- end of transmission list -->
    <!-- Gazebo-specific link properties -->
    <gazebo reference="base_link">
        <turnGravityOff>true</turnGravityOff>
        <plugin name="gazebo_ros_control">
            <robotNamespace>/</robotNamespace>
        </plugin>
    </gazebo>
    <gazebo reference="link_1_s">
        <turnGravityOff>true</turnGravityOff>
    </gazebo>
    <gazebo reference="link_2_l">
        <turnGravityOff>true</turnGravityOff>
    </gazebo>
    <gazebo reference="link_3_u">
        <turnGravityOff>true</turnGravityOff>
    </gazebo>
    <gazebo reference="link_4_r">
        <turnGravityOff>true</turnGravityOff>
    </gazebo>
    <gazebo reference="link_5_b">
        <turnGravityOff>true</turnGravityOff>
    </gazebo>
    <gazebo reference="link_6_t">
        <turnGravityOff>true</turnGravityOff>
    </gazebo>
    <!-- ros_control plugin -->
    <gazebo>
        <plugin filename="libgazebo_ros_control.so" name="gazebo_ros_control">
            <robotNamespace>/</robotNamespace>
            <robotSimType>gazebo_ros_control/DefaultRobotHWSim</robotSimType>
        </plugin>
    </gazebo>
    <!-- Fix robot to Gazebo world -->
    <link name="world" />
    <joint name="world-base_link-fixed" type="fixed">
        <parent link="world" />
        <child link="base_link" />
        <origin rpy="0.0 0.0 0.0" xyz="0.0 0.0 0.0" />
    </joint>
    <!-- <xacro:include filename="$(find gp4_gazebo)/urdf/belt.xacro"/> -->
    <!-- camera plugin -->
    <link name="camera">
        <collision>
            <origin rpy="0 0 1.5708" xyz="0 0 0" />
            <geometry>
                <mesh filename="package://gp4_description/meshes/camera.stl" />
            </geometry>
        </collision>
        <visual>
            <origin rpy="0 0 1.5708" xyz="0 0 0" />
            <geometry>
                <mesh filename="package://gp4_description/meshes/camera.stl" />
            </geometry>
        </visual>
        <inertial>
            <mass value="0.1" />
            <origin rpy="0 0 0" xyz="0 0 0" />
            <box_inertia m="0.1" x="0.05" y="0.1" z="0.1" />
            <inertia ixx="1e-6" ixy="0" ixz="0" iyy="1e-6" iyz="0" izz="1e-6" />
        </inertial>
    </link>
    <joint name="camera_optical_joint" type="fixed">
        <origin rpy="-1.5708 0 -1.5708" xyz="0 0 0" />
        <parent link="camera" />
        <child link="camera_frame_optical" />
    </joint>
    <link name="camera_frame_optical" />
    <joint name="camera_joint" type="fixed">
        <axis xyz="0 0 0" />
        <origin rpy="0 0 -1.5708" xyz="0 -0.2 0.4" />
        <parent link="base_link" />
        <child link="camera" />
    </joint>
    <!-- camera -->
    <gazebo reference="camera">
        <sensor name="camera1" type="depth">
            <update_rate>20</update_rate>
            <camera>
                <horizontal_fov>1.2</horizontal_fov>
                <image>
                    <width>640</width>
                    <!--640-->
                    <height>480</height>
                    <!--480-->
                    <format>RGB_INT8</format>
                </image>
                <clip>
                    <near>0.05</near>
                    <far>30</far>
                </clip>
            </camera>
            <plugin filename="libgazebo_ros_openni_kinect.so" name="camera_controller">
                <baseline>0.2</baseline>
                <alwaysOn>true</alwaysOn>
                <updateRate>1.0</updateRate>
                <cameraName>camera1</cameraName>
                <imageTopicName>/camera1/color/image_raw</imageTopicName>
                <cameraInfoTopicName>/camera1/color/camera_info</cameraInfoTopicName>
                <frameName>camera_frame_optical</frameName>
                <pointCloudCutoff>0.5</pointCloudCutoff>
                <pointCloudCutoffMax>3.0</pointCloudCutoffMax>
                <distortionK1>0.00000001</distortionK1>
                <distortionK2>0.00000001</distortionK2>
                <distortionK3>0.00000001</distortionK3>
                <distortionT1>0.00000001</distortionT1>
                <distortionT2>0.00000001</distortionT2>
                <CxPrime>0</CxPrime>
                <Cx>0</Cx>
                <Cy>0</Cy>
                <focalLength>0</focalLength>
                <hackBaseline>0</hackBaseline>
            </plugin>
        </sensor>
    </gazebo>
    <link name="robotiq_arg2f_base_link">
        <inertial>
            <origin rpy="0 0 0" xyz="8.625E-08 -4.6583E-06 0.03145" />
            <mass value="0.22652" />
            <inertia ixx="0.00020005" ixy="-4.2442E-10" ixz="-2.9069E-10" iyy="0.00017832" iyz="-3.4402E-08" izz="0.00013478" />
        </inertial>
        <visual>
            <origin rpy="0 0 0" xyz="0 0 0" />
            <geometry>
                <mesh filename="package://robotiq_2f_85_description/meshes/collision/robotiq_arg2f_base_link.stl" />
            </geometry>
            <material name="">
                <color rgba="0.1 0.1 0.1 1" />
            </material>
        </visual>
        <collision>
            <origin rpy="0 0 0" xyz="0 0 0" />
            <geometry>
                <mesh filename="package://robotiq_2f_85_description/meshes/collision/robotiq_arg2f_base_link.stl" />
            </geometry>
        </collision>
    </link>
    <link name="left_outer_knuckle">
        <!--<inertial>
        <origin xyz="-0.000200000000003065 0.0199435877845359 0.0292245259211331" rpy="0 0 0" />
        <mass value="0.00853198276973456" />
        <inertia ixx="2.89328108496468E-06" ixy="-1.57935047237397E-19" ixz="-1.93980378593255E-19" iyy="1.86719750325683E-06" iyz="-1.21858577871576E-06" izz="1.21905238907251E-06" />
        </inertial> -->
        <visual>
            <origin rpy="0 0 0" xyz="0 0 0" />
            <geometry>
                <mesh filename="package://robotiq_2f_85_description/meshes/visual/robotiq_arg2f_85_outer_knuckle.dae" scale="0.001 0.001 0.001" />
            </geometry>
            <material name="">
                <color rgba="0.792156862745098 0.819607843137255 0.933333333333333 1" />
            </material>
        </visual>
        <collision>
            <origin rpy="0 0 0" xyz="0 0 0" />
            <geometry>
                <mesh filename="package://robotiq_2f_85_description/meshes/collision/robotiq_arg2f_85_outer_knuckle.dae" scale="0.001 0.001 0.001" />
            </geometry>
        </collision>
        <inertial>
            <mass value="0.1" />
            <origin rpy="0 0 0" xyz="0 0 0" />
            <inertia ixx="0.03" ixy="0.0" ixz="0.0" iyy="0.03" iyz="0.0" izz="0.03" />
        </inertial>
    </link>
    <link name="left_outer_finger">
        <!--<inertial>
        <origin xyz="0.00030115855001899 0.0373907951953854 -0.0208027427000385" rpy="0 0 0" />
        <mass value="0.022614240507152" />
        <inertia ixx="1.52518312458174E-05" ixy="9.76583423954399E-10" ixz="-5.43838577022588E-10" iyy="6.17694243867776E-06" iyz="6.78636130740228E-06" izz="1.16494917907219E-05" />
        </inertial> -->
        <visual>
            <origin rpy="0 0 0" xyz="0 0 0" />
            <geometry>
                <mesh filename="package://robotiq_2f_85_description/meshes/visual/robotiq_arg2f_85_outer_finger.dae" scale="0.001 0.001 0.001" />
            </geometry>
            <material name="">
                <color rgba="0.1 0.1 0.1 1" />
            </material>
        </visual>
        <collision>
            <origin rpy="0 0 0" xyz="0 0 0" />
            <geometry>
                <mesh filename="package://robotiq_2f_85_description/meshes/collision/robotiq_arg2f_85_outer_finger.dae" scale="0.001 0.001 0.001" />
            </geometry>
        </collision>
        <inertial>
            <mass value="0.1" />
            <origin rpy="0 0 0" xyz="0 0 0" />
            <inertia ixx="0.03" ixy="0.0" ixz="0.0" iyy="0.03" iyz="0.0" izz="0.03" />
        </inertial>
    </link>
    <link name="left_inner_finger">
        <!--<inertial>
        <origin xyz="0.000299999999999317 0.0160078233491243 -0.0136945669206257" rpy="0 0 0" />
        <mass value="0.0104003125914103" />
        <inertia ixx="2.71909453810972E-06" ixy="1.35402465472579E-21" ixz="-7.1817349065269E-22" iyy="7.69100314106116E-07" iyz="6.74715432769696E-07" izz="2.30315190420171E-06" />
        </inertial> -->
        <visual>
            <origin rpy="0 0 0" xyz="0 0 0" />
            <geometry>
                <mesh filename="package://robotiq_2f_85_description/meshes/visual/robotiq_arg2f_85_inner_finger.dae" scale="0.001 0.001 0.001" />
            </geometry>
            <material name="">
                <color rgba="0.1 0.1 0.1 1" />
            </material>
        </visual>
        <collision>
            <origin rpy="0 0 0" xyz="0 0 0" />
            <geometry>
                <mesh filename="package://robotiq_2f_85_description/meshes/collision/robotiq_arg2f_85_inner_finger.dae" scale="0.001 0.001 0.001" />
            </geometry>
        </collision>
        <inertial>
            <mass value="0.1" />
            <origin rpy="0 0 0" xyz="0 0 0" />
            <inertia ixx="0.03" ixy="0.0" ixz="0.0" iyy="0.03" iyz="0.0" izz="0.03" />
        </inertial>
    </link>
    <link name="left_inner_finger_pad">
        <visual>
            <origin rpy="0 0 0" xyz="0 0 0" />
            <geometry>
                <box size="0.022 0.00635 0.0375" />
            </geometry>
            <material name="">
                <color rgba="0.9 0.9 0.9 1" />
            </material>
        </visual>
        <collision>
            <origin rpy="0 0 0" xyz="0 0 0" />
            <geometry>
                <box size="0.022 0.00635 0.0375" />
            </geometry>
            <material name="">
                <color rgba="0.9 0.0 0.0 1" />
            </material>
        </collision>
        <inertial>
            <mass value="0.1" />
            <origin rpy="0 0 0" xyz="0 0 0" />
            <inertia ixx="0.03" ixy="0.0" ixz="0.0" iyy="0.03" iyz="0.0" izz="0.03" />
        </inertial>
    </link>
    <link name="left_inner_knuckle">
        <!--<inertial>
        <origin xyz="0.000123011831763771 0.0507850843201817 0.00103968640075166" rpy="0 0 0" />
       <mass value="0.0271177346495152" />
        <inertia ixx="2.61910379223783E-05" ixy="-2.43616858946494E-07" ixz="-6.37789906117123E-09" iyy="2.8270243746167E-06" iyz="-5.37200748039765E-07" izz="2.83695868220296E-05" />
        </inertial> -->
        <visual>
            <origin rpy="0 0 0" xyz="0 0 0" />
            <geometry>
                <mesh filename="package://robotiq_2f_85_description/meshes/visual/robotiq_arg2f_85_inner_knuckle.dae" scale="0.001 0.001 0.001" />
            </geometry>
            <material name="">
                <color rgba="0.1 0.1 0.1 1" />
            </material>
        </visual>
        <collision>
            <origin rpy="0 0 0" xyz="0 0 0" />
            <geometry>
                <mesh filename="package://robotiq_2f_85_description/meshes/collision/robotiq_arg2f_85_inner_knuckle.dae" scale="0.001 0.001 0.001" />
            </geometry>
        </collision>
        <inertial>
            <mass value="0.1" />
            <origin rpy="0 0 0" xyz="0 0 0" />
            <inertia ixx="0.03" ixy="0.0" ixz="0.0" iyy="0.03" iyz="0.0" izz="0.03" />
        </inertial>
    </link>
    <link name="right_outer_knuckle">
        <!--<inertial>
        <origin xyz="-0.000200000000003065 0.0199435877845359 0.0292245259211331" rpy="0 0 0" />
        <mass value="0.00853198276973456" />
        <inertia ixx="2.89328108496468E-06" ixy="-1.57935047237397E-19" ixz="-1.93980378593255E-19" iyy="1.86719750325683E-06" iyz="-1.21858577871576E-06" izz="1.21905238907251E-06" />
        </inertial> -->
        <visual>
            <origin rpy="0 0 0" xyz="0 0 0" />
            <geometry>
                <mesh filename="package://robotiq_2f_85_description/meshes/visual/robotiq_arg2f_85_outer_knuckle.dae" scale="0.001 0.001 0.001" />
            </geometry>
            <material name="">
                <color rgba="0.792156862745098 0.819607843137255 0.933333333333333 1" />
            </material>
        </visual>
        <collision>
            <origin rpy="0 0 0" xyz="0 0 0" />
            <geometry>
                <mesh filename="package://robotiq_2f_85_description/meshes/collision/robotiq_arg2f_85_outer_knuckle.dae" scale="0.001 0.001 0.001" />
            </geometry>
        </collision>
        <inertial>
            <mass value="0.1" />
            <origin rpy="0 0 0" xyz="0 0 0" />
            <inertia ixx="0.03" ixy="0.0" ixz="0.0" iyy="0.03" iyz="0.0" izz="0.03" />
        </inertial>
    </link>
    <link name="right_outer_finger">
        <!--<inertial>
        <origin xyz="0.00030115855001899 0.0373907951953854 -0.0208027427000385" rpy="0 0 0" />
        <mass value="0.022614240507152" />
        <inertia ixx="1.52518312458174E-05" ixy="9.76583423954399E-10" ixz="-5.43838577022588E-10" iyy="6.17694243867776E-06" iyz="6.78636130740228E-06" izz="1.16494917907219E-05" />
        </inertial> -->
        <visual>
            <origin rpy="0 0 0" xyz="0 0 0" />
            <geometry>
                <mesh filename="package://robotiq_2f_85_description/meshes/visual/robotiq_arg2f_85_outer_finger.dae" scale="0.001 0.001 0.001" />
            </geometry>
            <material name="">
                <color rgba="0.1 0.1 0.1 1" />
            </material>
        </visual>
        <collision>
            <origin rpy="0 0 0" xyz="0 0 0" />
            <geometry>
                <mesh filename="package://robotiq_2f_85_description/meshes/collision/robotiq_arg2f_85_outer_finger.dae" scale="0.001 0.001 0.001" />
            </geometry>
        </collision>
        <inertial>
            <mass value="0.1" />
            <origin rpy="0 0 0" xyz="0 0 0" />
            <inertia ixx="0.03" ixy="0.0" ixz="0.0" iyy="0.03" iyz="0.0" izz="0.03" />
        </inertial>
    </link>
    <link name="right_inner_finger">
        <!--<inertial>
        <origin xyz="0.000299999999999317 0.0160078233491243 -0.0136945669206257" rpy="0 0 0" />
        <mass value="0.0104003125914103" />
        <inertia ixx="2.71909453810972E-06" ixy="1.35402465472579E-21" ixz="-7.1817349065269E-22" iyy="7.69100314106116E-07" iyz="6.74715432769696E-07" izz="2.30315190420171E-06" />
        </inertial> -->
        <visual>
            <origin rpy="0 0 0" xyz="0 0 0" />
            <geometry>
                <mesh filename="package://robotiq_2f_85_description/meshes/visual/robotiq_arg2f_85_inner_finger.dae" scale="0.001 0.001 0.001" />
            </geometry>
            <material name="">
                <color rgba="0.1 0.1 0.1 1" />
            </material>
        </visual>
        <collision>
            <origin rpy="0 0 0" xyz="0 0 0" />
            <geometry>
                <mesh filename="package://robotiq_2f_85_description/meshes/collision/robotiq_arg2f_85_inner_finger.dae" scale="0.001 0.001 0.001" />
            </geometry>
        </collision>
        <inertial>
            <mass value="0.1" />
            <origin rpy="0 0 0" xyz="0 0 0" />
            <inertia ixx="0.03" ixy="0.0" ixz="0.0" iyy="0.03" iyz="0.0" izz="0.03" />
        </inertial>
    </link>
    <link name="right_inner_finger_pad">
        <visual>
            <origin rpy="0 0 0" xyz="0 0 0" />
            <geometry>
                <box size="0.022 0.00635 0.0375" />
            </geometry>
            <material name="">
                <color rgba="0.9 0.9 0.9 1" />
            </material>
        </visual>
        <collision>
            <origin rpy="0 0 0" xyz="0 0 0" />
            <geometry>
                <box size="0.022 0.00635 0.0375" />
            </geometry>
            <material name="">
                <color rgba="0.9 0.0 0.0 1" />
            </material>
        </collision>
        <inertial>
            <mass value="0.1" />
            <origin rpy="0 0 0" xyz="0 0 0" />
            <inertia ixx="0.03" ixy="0.0" ixz="0.0" iyy="0.03" iyz="0.0" izz="0.03" />
        </inertial>
    </link>
    <link name="right_inner_knuckle">
        <!--<inertial>
        <origin xyz="0.000123011831763771 0.0507850843201817 0.00103968640075166" rpy="0 0 0" />
       <mass value="0.0271177346495152" />
        <inertia ixx="2.61910379223783E-05" ixy="-2.43616858946494E-07" ixz="-6.37789906117123E-09" iyy="2.8270243746167E-06" iyz="-5.37200748039765E-07" izz="2.83695868220296E-05" />
        </inertial> -->
        <visual>
            <origin rpy="0 0 0" xyz="0 0 0" />
            <geometry>
                <mesh filename="package://robotiq_2f_85_description/meshes/visual/robotiq_arg2f_85_inner_knuckle.dae" scale="0.001 0.001 0.001" />
            </geometry>
            <material name="">
                <color rgba="0.1 0.1 0.1 1" />
            </material>
        </visual>
        <collision>
            <origin rpy="0 0 0" xyz="0 0 0" />
            <geometry>
                <mesh filename="package://robotiq_2f_85_description/meshes/collision/robotiq_arg2f_85_inner_knuckle.dae" scale="0.001 0.001 0.001" />
            </geometry>
        </collision>
        <inertial>
            <mass value="0.1" />
            <origin rpy="0 0 0" xyz="0 0 0" />
            <inertia ixx="0.03" ixy="0.0" ixz="0.0" iyy="0.03" iyz="0.0" izz="0.03" />
        </inertial>
    </link>
    <joint name="finger_joint" type="revolute">
        <origin rpy="0 0 3.141592653589793" xyz="0 -0.0306011 0.054904" />
        <parent link="robotiq_arg2f_base_link" />
        <child link="left_outer_knuckle" />
        <axis xyz="1 0 0" />
        <limit effort="1000" lower="0" upper="0.8" velocity="2.0" />
    </joint>
    <joint name="left_outer_finger_joint" type="fixed">
        <origin rpy="0 0 0" xyz="0 0.0315 -0.0041" />
        <parent link="left_outer_knuckle" />
        <child link="left_outer_finger" />
        <axis xyz="1 0 0" />
    </joint>
    <joint name="left_inner_knuckle_joint" type="revolute">
        <!-- <origin xyz="0 ${reflect * -0.0127} 0.06142" rpy="${pi / 2 + .725} 0 ${(reflect - 1) * pi / 2}" /> -->
        <origin rpy="0 0 3.141592653589793" xyz="0 -0.0127 0.06142" />
        <parent link="robotiq_arg2f_base_link" />
        <child link="left_inner_knuckle" />
        <axis xyz="1 0 0" />
        <limit effort="1000" lower="0" upper="0.8757" velocity="2.0" />
        <mimic joint="finger_joint" multiplier="1" offset="0" />
    </joint>
    <joint name="left_inner_finger_joint" type="revolute">
        <origin rpy="0 0 0" xyz="0 0.0061 0.0471" />
        <parent link="left_outer_finger" />
        <child link="left_inner_finger" />
        <axis xyz="1 0 0" />
        <limit effort="1000" lower="-0.8757" upper="0.8757" velocity="2.0" />
        <mimic joint="finger_joint" multiplier="-1" offset="0" />
    </joint>
    <joint name="left_inner_finger_pad_joint" type="fixed">
        <origin rpy="0 0 0" xyz="0 -0.0220203446692936 0.03242" />
        <parent link="left_inner_finger" />
        <child link="left_inner_finger_pad" />
        <axis xyz="0 0 1" />
    </joint>
    <joint name="right_outer_knuckle_joint" type="revolute">
        <origin rpy="0 0 0" xyz="0 0.0306011 0.054904" />
        <parent link="robotiq_arg2f_base_link" />
        <child link="right_outer_knuckle" />
        <axis xyz="1 0 0" />
        <limit effort="1000" lower="0" upper="0.81" velocity="2.0" />
        <mimic joint="finger_joint" multiplier="1" offset="0" />
    </joint>
    <joint name="right_outer_finger_joint" type="fixed">
        <origin rpy="0 0 0" xyz="0 0.0315 -0.0041" />
        <parent link="right_outer_knuckle" />
        <child link="right_outer_finger" />
        <axis xyz="1 0 0" />
    </joint>
    <joint name="right_inner_knuckle_joint" type="revolute">
        <!-- <origin xyz="0 ${reflect * -0.0127} 0.06142" rpy="${pi / 2 + .725} 0 ${(reflect - 1) * pi / 2}" /> -->
        <origin rpy="0 0 0.0" xyz="0 0.0127 0.06142" />
        <parent link="robotiq_arg2f_base_link" />
        <child link="right_inner_knuckle" />
        <axis xyz="1 0 0" />
        <limit effort="1000" lower="0" upper="0.8757" velocity="2.0" />
        <mimic joint="finger_joint" multiplier="1" offset="0" />
    </joint>
    <joint name="right_inner_finger_joint" type="revolute">
        <origin rpy="0 0 0" xyz="0 0.0061 0.0471" />
        <parent link="right_outer_finger" />
        <child link="right_inner_finger" />
        <axis xyz="1 0 0" />
        <limit effort="1000" lower="-0.8757" upper="0.8757" velocity="2.0" />
        <mimic joint="finger_joint" multiplier="-1" offset="0" />
    </joint>
    <joint name="right_inner_finger_pad_joint" type="fixed">
        <origin rpy="0 0 0" xyz="0 -0.0220203446692936 0.03242" />
        <parent link="right_inner_finger" />
        <child link="right_inner_finger_pad" />
        <axis xyz="0 0 1" />
    </joint>
    <transmission name="finger_joint_trans">
        <type>transmission_interface/SimpleTransmission</type>
        <joint name="finger_joint">
            <hardwareInterface>hardware_interface/PositionJointInterface</hardwareInterface>
        </joint>
        <actuator name="finger_joint_motor">
            <mechanicalReduction>1</mechanicalReduction>
            <hardwareInterface>hardware_interface/PositionJointInterface</hardwareInterface>
        </actuator>
    </transmission>
    <link name="coupling_link">
        <visual>
            <origin rpy="0 0 1.5707963267948966" xyz="0 0 0.007" />
            <geometry>
                <mesh filename="package://robotiq_2f_85_description/meshes/visual/robotiq_gripper_coupling.stl" scale="0.001 0.001 0.001" />
            </geometry>
            <material name="">
                <color rgba="0.1 0.1 0.1 1" />
            </material>
        </visual>
        <collision>
            <origin rpy="0 0 0" xyz="0 0 0" />
            <geometry>
                <mesh filename="package://robotiq_2f_85_description/meshes/visual/robotiq_gripper_coupling.stl" scale="0.001 0.001 0.001" />
            </geometry>
        </collision>
        <inertial>
            <mass value="0.1" />
            <origin rpy="0 0 0" xyz="0 0 0" />
            <inertia ixx="0.03" ixy="0.0" ixz="0.0" iyy="0.03" iyz="0.0" izz="0.03" />
        </inertial>
    </link>
    <joint name="coupling_joint" type="fixed">
        <origin rpy="0 0 0" xyz="0 0 0.011" />
        <parent link="coupling_link" />
        <child link="robotiq_arg2f_base_link" />
    </joint>
    <joint name="gp4_joint_gripper_support" type="fixed">
        <parent link="tool0" />
        <child link="coupling_link" />
        <origin rpy="0 0 0" xyz="0 0 -0.003" />
    </joint>
    <!-- end-effector point -->
    <joint name="end_effector_point" type="fixed">
        <origin rpy="0 0 0" xyz="0 0 0.2015" />
        <parent link="tool0" />
        <child link="end_effector_point" />
    </joint>
    <link name="end_effector_point">
        <visual>
            <origin rpy="0 0 0" xyz="0 0 -0.1" />
            <geometry>
                <box size="0.002 0.002 0.002" />
            </geometry>
            <material name="">
                <color rgba="0.8 0.0 0.0 1.0" />
            </material>
        </visual>
        <!-- <collision>
  	  <origin rpy="0 0 0" xyz="0 0 -0.1"/>
  	  <geometry>
  	     <box size="0.002 0.002 0.002"/>	  
  	  </geometry> 
  	</collision> -->
        <inertial>
            <origin rpy="0 0 0" xyz="0.0 0.0 0.0" />
            <mass value="0.001" />
            <inertia ixx="1.0e-06" ixy="0.0" ixz="0.0" iyy="1.0e-06" iyz="0.0" izz="1.0e-06" />
        </inertial>
    </link>
    <!-- GP4 -->
    <transmission name="trans_left_inner_knuckle_joint">
        <type>transmission_interface/SimpleTransmission</type>
        <joint name="left_inner_knuckle_joint">
            <hardwareInterface>hardware_interface/PositionJointInterface</hardwareInterface>
        </joint>
        <actuator name="left_inner_knuckle_joint_motor">
            <hardwareInterface>hardware_interface/PositionJointInterface</hardwareInterface>
            <mechanicalReduction>1</mechanicalReduction>
        </actuator>
    </transmission>
    <transmission name="trans_left_inner_finger_joint">
        <type>transmission_interface/SimpleTransmission</type>
        <joint name="left_inner_finger_joint">
            <hardwareInterface>hardware_interface/PositionJointInterface</hardwareInterface>
        </joint>
        <actuator name="left_inner_finger_joint_motor">
            <hardwareInterface>hardware_interface/PositionJointInterface</hardwareInterface>
            <mechanicalReduction>1</mechanicalReduction>
        </actuator>
    </transmission>
    <transmission name="trans_right_outer_knuckle_joint">
        <type>transmission_interface/SimpleTransmission</type>
        <joint name="right_outer_knuckle_joint">
            <hardwareInterface>hardware_interface/PositionJointInterface</hardwareInterface>
        </joint>
        <actuator name="right_outer_knuckle_joint_motor">
            <hardwareInterface>hardware_interface/PositionJointInterface</hardwareInterface>
            <mechanicalReduction>1</mechanicalReduction>
        </actuator>
    </transmission>
    <transmission name="trans_right_inner_knuckle_joint">
        <type>transmission_interface/SimpleTransmission</type>
        <joint name="right_inner_knuckle_joint">
            <hardwareInterface>hardware_interface/PositionJointInterface</hardwareInterface>
        </joint>
        <actuator name="right_inner_knuckle_joint_motor">
            <hardwareInterface>hardware_interface/PositionJointInterface</hardwareInterface>
            <mechanicalReduction>1</mechanicalReduction>
        </actuator>
    </transmission>
    <transmission name="trans_right_inner_finger_joint">
        <type>transmission_interface/SimpleTransmission</type>
        <joint name="right_inner_finger_joint">
            <hardwareInterface>hardware_interface/PositionJointInterface</hardwareInterface>
        </joint>
        <actuator name="right_inner_finger_joint_motor">
            <hardwareInterface>hardware_interface/PositionJointInterface</hardwareInterface>
            <mechanicalReduction>1</mechanicalReduction>
        </actuator>
    </transmission>
    <gazebo>
        <!-- loading plugin: mimic joints works in gazebo now -->
        <plugin filename="libroboticsgroup_upatras_gazebo_mimic_joint_plugin.so" name="mimic_robotiq_85_1">
            <joint>finger_joint</joint>
            <mimicJoint>right_outer_knuckle_joint</mimicJoint>
            <multiplier>1.0</multiplier>
            <!--<offset>0.0</offset-->
        </plugin>
        <plugin filename="libroboticsgroup_upatras_gazebo_mimic_joint_plugin.so" name="mimic_robotiq_85_5">
            <joint>finger_joint</joint>
            <mimicJoint>left_inner_finger_joint</mimicJoint>
            <multiplier>-1.0</multiplier>
            <!--offset>0.0</offset-->
        </plugin>
        <plugin filename="libroboticsgroup_upatras_gazebo_mimic_joint_plugin.so" name="mimic_robotiq_85_4">
            <joint>finger_joint</joint>
            <mimicJoint>right_inner_finger_joint</mimicJoint>
            <multiplier>-1.0</multiplier>
            <!--offset>0.0</offset-->
        </plugin>
        <plugin filename="libroboticsgroup_upatras_gazebo_mimic_joint_plugin.so" name="mimic_robotiq_85_2">
            <joint>finger_joint</joint>
            <mimicJoint>left_inner_knuckle_joint</mimicJoint>
            <multiplier>1.0</multiplier>
            <!--<offset>0.0</offset-->
        </plugin>
        <plugin filename="libroboticsgroup_upatras_gazebo_mimic_joint_plugin.so" name="mimic_robotiq_85_3">
            <joint>finger_joint</joint>
            <mimicJoint>right_inner_knuckle_joint</mimicJoint>
            <multiplier>1.0</multiplier>
            <!--<offset>0.0</offset-->
        </plugin>
    </gazebo>
    <!-- Plugin -->
    <gazebo>
        <plugin filename="libgazebo_grasp_fix.so" name="gazebo_grasp_fix">
            <arm>
                <arm_name>motoman_gp4</arm_name>
                <palm_link>link_6_t</palm_link>
                <gripper_link>left_outer_knuckle</gripper_link>
                <gripper_link>right_outer_knuckle</gripper_link>
                <gripper_link>left_inner_finger</gripper_link>
                <gripper_link>right_inner_finger</gripper_link>
            </arm>
            <forces_angle_tolerance>90</forces_angle_tolerance>
            <update_rate>4</update_rate>
            <grip_count_threshold>4</grip_count_threshold>
            <max_grip_count>8</max_grip_count>
            <release_tolerance>0.005</release_tolerance>
            <disable_collisions_on_attach>false</disable_collisions_on_attach>
            <contact_topic>__default_topic__</contact_topic>
        </plugin>
    </gazebo>
</robot>

